6349167727:AAGAJM-Eb7Mcib3T_XUVuvojG6w38duG4cg
Traceback (most recent call last):
  File "/home/pi/Documents/academIA/src/Telegram.py", line 17, in <module>
    from langchain.embeddings.openai import OpenAIEmbeddings
  File "/home/pi/.local/lib/python3.9/site-packages/langchain/embeddings/__init__.py", line 56, in <module>
    from langchain.embeddings.sagemaker_endpoint import SagemakerEndpointEmbeddings
  File "/home/pi/.local/lib/python3.9/site-packages/langchain/embeddings/sagemaker_endpoint.py", line 3, in <module>
    from langchain.llms.sagemaker_endpoint import ContentHandlerBase
  File "/home/pi/.local/lib/python3.9/site-packages/langchain/llms/sagemaker_endpoint.py", line 125, in <module>
    class SagemakerEndpoint(LLM):
  File "/home/pi/.local/lib/python3.9/site-packages/pydantic/main.py", line 197, in __new__
    fields[ann_name] = ModelField.infer(
  File "/home/pi/.local/lib/python3.9/site-packages/pydantic/fields.py", line 506, in infer
    return cls(
  File "/home/pi/.local/lib/python3.9/site-packages/pydantic/fields.py", line 436, in __init__
    self.prepare()
  File "/home/pi/.local/lib/python3.9/site-packages/pydantic/fields.py", line 557, in prepare
    self.populate_validators()
  File "/home/pi/.local/lib/python3.9/site-packages/pydantic/fields.py", line 842, in populate_validators
    if class_validators_:
KeyboardInterrupt
2023-10-07 13:55:08,827 (__init__.py:960 MainThread) ERROR - TeleBot: "Infinity polling exception: tzinfo argument must be None or of a tzinfo subclass, not type 'str'"
2023-10-07 13:55:08,829 (__init__.py:962 MainThread) ERROR - TeleBot: "Exception traceback:
Traceback (most recent call last):
  File "/home/pi/.local/lib/python3.9/site-packages/telebot/__init__.py", line 955, in infinity_polling
    self.polling(non_stop=True, timeout=timeout, long_polling_timeout=long_polling_timeout,
  File "/home/pi/.local/lib/python3.9/site-packages/telebot/__init__.py", line 1043, in polling
    self.__threaded_polling(non_stop=non_stop, interval=interval, timeout=timeout, long_polling_timeout=long_polling_timeout,
  File "/home/pi/.local/lib/python3.9/site-packages/telebot/__init__.py", line 1118, in __threaded_polling
    raise e
  File "/home/pi/.local/lib/python3.9/site-packages/telebot/__init__.py", line 1074, in __threaded_polling
    self.worker_pool.raise_exceptions()
  File "/home/pi/.local/lib/python3.9/site-packages/telebot/util.py", line 147, in raise_exceptions
    raise self.exception_info
  File "/home/pi/.local/lib/python3.9/site-packages/telebot/util.py", line 90, in run
    task(*args, **kwargs)
  File "/home/pi/.local/lib/python3.9/site-packages/telebot/__init__.py", line 6801, in _run_middlewares_and_handler
    result = handler['function'](message)
  File "/home/pi/Documents/academIA/src/Telegram.py", line 89, in echo_all
    'timestamp': dt.datetime.now(tz='Madrid')
TypeError: tzinfo argument must be None or of a tzinfo subclass, not type 'str'
"
2023-10-07 13:55:44,809 (__init__.py:960 MainThread) ERROR - TeleBot: "Infinity polling exception: tzinfo argument must be None or of a tzinfo subclass, not type 'str'"
2023-10-07 13:55:44,810 (__init__.py:962 MainThread) ERROR - TeleBot: "Exception traceback:
Traceback (most recent call last):
  File "/home/pi/.local/lib/python3.9/site-packages/telebot/__init__.py", line 955, in infinity_polling
    self.polling(non_stop=True, timeout=timeout, long_polling_timeout=long_polling_timeout,
  File "/home/pi/.local/lib/python3.9/site-packages/telebot/__init__.py", line 1043, in polling
    self.__threaded_polling(non_stop=non_stop, interval=interval, timeout=timeout, long_polling_timeout=long_polling_timeout,
  File "/home/pi/.local/lib/python3.9/site-packages/telebot/__init__.py", line 1118, in __threaded_polling
    raise e
  File "/home/pi/.local/lib/python3.9/site-packages/telebot/__init__.py", line 1074, in __threaded_polling
    self.worker_pool.raise_exceptions()
  File "/home/pi/.local/lib/python3.9/site-packages/telebot/util.py", line 147, in raise_exceptions
    raise self.exception_info
  File "/home/pi/.local/lib/python3.9/site-packages/telebot/util.py", line 90, in run
    task(*args, **kwargs)
  File "/home/pi/.local/lib/python3.9/site-packages/telebot/__init__.py", line 6801, in _run_middlewares_and_handler
    result = handler['function'](message)
  File "/home/pi/Documents/academIA/src/Telegram.py", line 89, in echo_all
    'timestamp': dt.datetime.now(tz='Madrid')
TypeError: tzinfo argument must be None or of a tzinfo subclass, not type 'str'
"
2023-10-07 14:04:28,522 (__init__.py:960 MainThread) ERROR - TeleBot: "Infinity polling exception: tzinfo argument must be None or of a tzinfo subclass, not type 'str'"
2023-10-07 14:04:28,522 (__init__.py:962 MainThread) ERROR - TeleBot: "Exception traceback:
Traceback (most recent call last):
  File "/home/pi/.local/lib/python3.9/site-packages/telebot/__init__.py", line 955, in infinity_polling
    self.polling(non_stop=True, timeout=timeout, long_polling_timeout=long_polling_timeout,
  File "/home/pi/.local/lib/python3.9/site-packages/telebot/__init__.py", line 1043, in polling
    self.__threaded_polling(non_stop=non_stop, interval=interval, timeout=timeout, long_polling_timeout=long_polling_timeout,
  File "/home/pi/.local/lib/python3.9/site-packages/telebot/__init__.py", line 1118, in __threaded_polling
    raise e
  File "/home/pi/.local/lib/python3.9/site-packages/telebot/__init__.py", line 1074, in __threaded_polling
    self.worker_pool.raise_exceptions()
  File "/home/pi/.local/lib/python3.9/site-packages/telebot/util.py", line 147, in raise_exceptions
    raise self.exception_info
  File "/home/pi/.local/lib/python3.9/site-packages/telebot/util.py", line 90, in run
    task(*args, **kwargs)
  File "/home/pi/.local/lib/python3.9/site-packages/telebot/__init__.py", line 6801, in _run_middlewares_and_handler
    result = handler['function'](message)
  File "/home/pi/Documents/academIA/src/Telegram.py", line 89, in echo_all
    ts_diferencia = ts_respuesta - ts_mensaje
TypeError: tzinfo argument must be None or of a tzinfo subclass, not type 'str'
"
2023-10-07 14:05:36,384 (__init__.py:960 MainThread) ERROR - TeleBot: "Infinity polling exception: tzinfo argument must be None or of a tzinfo subclass, not type 'str'"
2023-10-07 14:05:36,384 (__init__.py:962 MainThread) ERROR - TeleBot: "Exception traceback:
Traceback (most recent call last):
  File "/home/pi/.local/lib/python3.9/site-packages/telebot/__init__.py", line 955, in infinity_polling
    self.polling(non_stop=True, timeout=timeout, long_polling_timeout=long_polling_timeout,
  File "/home/pi/.local/lib/python3.9/site-packages/telebot/__init__.py", line 1043, in polling
    self.__threaded_polling(non_stop=non_stop, interval=interval, timeout=timeout, long_polling_timeout=long_polling_timeout,
  File "/home/pi/.local/lib/python3.9/site-packages/telebot/__init__.py", line 1118, in __threaded_polling
    raise e
  File "/home/pi/.local/lib/python3.9/site-packages/telebot/__init__.py", line 1074, in __threaded_polling
    self.worker_pool.raise_exceptions()
  File "/home/pi/.local/lib/python3.9/site-packages/telebot/util.py", line 147, in raise_exceptions
    raise self.exception_info
  File "/home/pi/.local/lib/python3.9/site-packages/telebot/util.py", line 90, in run
    task(*args, **kwargs)
  File "/home/pi/.local/lib/python3.9/site-packages/telebot/__init__.py", line 6801, in _run_middlewares_and_handler
    result = handler['function'](message)
  File "/home/pi/Documents/academIA/src/Telegram.py", line 89, in echo_all
    ts_diferencia = ts_respuesta - ts_mensaje
TypeError: tzinfo argument must be None or of a tzinfo subclass, not type 'str'
"
2023-10-07 14:06:28,963 (__init__.py:960 MainThread) ERROR - TeleBot: "Infinity polling exception: tzinfo argument must be None or of a tzinfo subclass, not type 'str'"
2023-10-07 14:06:28,965 (__init__.py:962 MainThread) ERROR - TeleBot: "Exception traceback:
Traceback (most recent call last):
  File "/home/pi/.local/lib/python3.9/site-packages/telebot/__init__.py", line 955, in infinity_polling
    self.polling(non_stop=True, timeout=timeout, long_polling_timeout=long_polling_timeout,
  File "/home/pi/.local/lib/python3.9/site-packages/telebot/__init__.py", line 1043, in polling
    self.__threaded_polling(non_stop=non_stop, interval=interval, timeout=timeout, long_polling_timeout=long_polling_timeout,
  File "/home/pi/.local/lib/python3.9/site-packages/telebot/__init__.py", line 1118, in __threaded_polling
    raise e
  File "/home/pi/.local/lib/python3.9/site-packages/telebot/__init__.py", line 1074, in __threaded_polling
    self.worker_pool.raise_exceptions()
  File "/home/pi/.local/lib/python3.9/site-packages/telebot/util.py", line 147, in raise_exceptions
    raise self.exception_info
  File "/home/pi/.local/lib/python3.9/site-packages/telebot/util.py", line 90, in run
    task(*args, **kwargs)
  File "/home/pi/.local/lib/python3.9/site-packages/telebot/__init__.py", line 6801, in _run_middlewares_and_handler
    result = handler['function'](message)
  File "/home/pi/Documents/academIA/src/Telegram.py", line 89, in echo_all
    ts_diferencia = ts_respuesta - ts_mensaje
TypeError: tzinfo argument must be None or of a tzinfo subclass, not type 'str'
"
2023-10-07 14:07:02,968 (__init__.py:960 MainThread) ERROR - TeleBot: "Infinity polling exception: tzinfo argument must be None or of a tzinfo subclass, not type 'str'"
2023-10-07 14:07:02,969 (__init__.py:962 MainThread) ERROR - TeleBot: "Exception traceback:
Traceback (most recent call last):
  File "/home/pi/.local/lib/python3.9/site-packages/telebot/__init__.py", line 955, in infinity_polling
    self.polling(non_stop=True, timeout=timeout, long_polling_timeout=long_polling_timeout,
  File "/home/pi/.local/lib/python3.9/site-packages/telebot/__init__.py", line 1043, in polling
    self.__threaded_polling(non_stop=non_stop, interval=interval, timeout=timeout, long_polling_timeout=long_polling_timeout,
  File "/home/pi/.local/lib/python3.9/site-packages/telebot/__init__.py", line 1118, in __threaded_polling
    raise e
  File "/home/pi/.local/lib/python3.9/site-packages/telebot/__init__.py", line 1074, in __threaded_polling
    self.worker_pool.raise_exceptions()
  File "/home/pi/.local/lib/python3.9/site-packages/telebot/util.py", line 147, in raise_exceptions
    raise self.exception_info
  File "/home/pi/.local/lib/python3.9/site-packages/telebot/util.py", line 90, in run
    task(*args, **kwargs)
  File "/home/pi/.local/lib/python3.9/site-packages/telebot/__init__.py", line 6801, in _run_middlewares_and_handler
    result = handler['function'](message)
  File "/home/pi/Documents/academIA/src/Telegram.py", line 89, in echo_all
    ts_diferencia = ts_respuesta - ts_mensaje
TypeError: tzinfo argument must be None or of a tzinfo subclass, not type 'str'
"
2023-10-07 14:07:29,318 (__init__.py:960 MainThread) ERROR - TeleBot: "Infinity polling exception: tzinfo argument must be None or of a tzinfo subclass, not type 'str'"
2023-10-07 14:07:29,319 (__init__.py:962 MainThread) ERROR - TeleBot: "Exception traceback:
Traceback (most recent call last):
  File "/home/pi/.local/lib/python3.9/site-packages/telebot/__init__.py", line 955, in infinity_polling
    self.polling(non_stop=True, timeout=timeout, long_polling_timeout=long_polling_timeout,
  File "/home/pi/.local/lib/python3.9/site-packages/telebot/__init__.py", line 1043, in polling
    self.__threaded_polling(non_stop=non_stop, interval=interval, timeout=timeout, long_polling_timeout=long_polling_timeout,
  File "/home/pi/.local/lib/python3.9/site-packages/telebot/__init__.py", line 1118, in __threaded_polling
    raise e
  File "/home/pi/.local/lib/python3.9/site-packages/telebot/__init__.py", line 1074, in __threaded_polling
    self.worker_pool.raise_exceptions()
  File "/home/pi/.local/lib/python3.9/site-packages/telebot/util.py", line 147, in raise_exceptions
    raise self.exception_info
  File "/home/pi/.local/lib/python3.9/site-packages/telebot/util.py", line 90, in run
    task(*args, **kwargs)
  File "/home/pi/.local/lib/python3.9/site-packages/telebot/__init__.py", line 6801, in _run_middlewares_and_handler
    result = handler['function'](message)
  File "/home/pi/Documents/academIA/src/Telegram.py", line 89, in echo_all
    ts_diferencia = ts_respuesta - ts_mensaje
TypeError: tzinfo argument must be None or of a tzinfo subclass, not type 'str'
"
2023-10-07 14:08:10,297 (__init__.py:960 MainThread) ERROR - TeleBot: "Infinity polling exception: tzinfo argument must be None or of a tzinfo subclass, not type 'str'"
2023-10-07 14:08:10,298 (__init__.py:962 MainThread) ERROR - TeleBot: "Exception traceback:
Traceback (most recent call last):
  File "/home/pi/.local/lib/python3.9/site-packages/telebot/__init__.py", line 955, in infinity_polling
    self.polling(non_stop=True, timeout=timeout, long_polling_timeout=long_polling_timeout,
  File "/home/pi/.local/lib/python3.9/site-packages/telebot/__init__.py", line 1043, in polling
    self.__threaded_polling(non_stop=non_stop, interval=interval, timeout=timeout, long_polling_timeout=long_polling_timeout,
  File "/home/pi/.local/lib/python3.9/site-packages/telebot/__init__.py", line 1118, in __threaded_polling
    raise e
  File "/home/pi/.local/lib/python3.9/site-packages/telebot/__init__.py", line 1074, in __threaded_polling
    self.worker_pool.raise_exceptions()
  File "/home/pi/.local/lib/python3.9/site-packages/telebot/util.py", line 147, in raise_exceptions
    raise self.exception_info
  File "/home/pi/.local/lib/python3.9/site-packages/telebot/util.py", line 90, in run
    task(*args, **kwargs)
  File "/home/pi/.local/lib/python3.9/site-packages/telebot/__init__.py", line 6801, in _run_middlewares_and_handler
    result = handler['function'](message)
  File "/home/pi/Documents/academIA/src/Telegram.py", line 89, in echo_all
    ts_diferencia = ts_respuesta - ts_mensaje
TypeError: tzinfo argument must be None or of a tzinfo subclass, not type 'str'
"
Retrying langchain.chat_models.openai.ChatOpenAI.completion_with_retry.<locals>._completion_with_retry in 4.0 seconds as it raised ServiceUnavailableError: The server is overloaded or not ready yet..
2023-10-08 23:54:33,371 (__init__.py:960 MainThread) ERROR - TeleBot: "Infinity polling exception: Bot token is not defined"
2023-10-08 23:54:33,377 (__init__.py:962 MainThread) ERROR - TeleBot: "Exception traceback:
Traceback (most recent call last):
  File "/home/pi/.local/lib/python3.9/site-packages/telebot/__init__.py", line 955, in infinity_polling
    self.polling(non_stop=True, timeout=timeout, long_polling_timeout=long_polling_timeout,
  File "/home/pi/.local/lib/python3.9/site-packages/telebot/__init__.py", line 1040, in polling
    logger.info('Starting your bot with username: [@%s]', self.user.username)
  File "/home/pi/.local/lib/python3.9/site-packages/telebot/__init__.py", line 273, in user
    self._user = self.get_me()
  File "/home/pi/.local/lib/python3.9/site-packages/telebot/__init__.py", line 1236, in get_me
    result = apihelper.get_me(self.token)
  File "/home/pi/.local/lib/python3.9/site-packages/telebot/apihelper.py", line 196, in get_me
    return _make_request(token, method_url)
  File "/home/pi/.local/lib/python3.9/site-packages/telebot/apihelper.py", line 80, in _make_request
    raise Exception('Bot token is not defined')
Exception: Bot token is not defined
"
2023-10-08 23:54:36,381 (__init__.py:960 MainThread) ERROR - TeleBot: "Infinity polling exception: Bot token is not defined"
2023-10-08 23:54:36,381 (__init__.py:962 MainThread) ERROR - TeleBot: "Exception traceback:
Traceback (most recent call last):
  File "/home/pi/.local/lib/python3.9/site-packages/telebot/__init__.py", line 955, in infinity_polling
    self.polling(non_stop=True, timeout=timeout, long_polling_timeout=long_polling_timeout,
  File "/home/pi/.local/lib/python3.9/site-packages/telebot/__init__.py", line 1040, in polling
    logger.info('Starting your bot with username: [@%s]', self.user.username)
  File "/home/pi/.local/lib/python3.9/site-packages/telebot/__init__.py", line 273, in user
    self._user = self.get_me()
  File "/home/pi/.local/lib/python3.9/site-packages/telebot/__init__.py", line 1236, in get_me
    result = apihelper.get_me(self.token)
  File "/home/pi/.local/lib/python3.9/site-packages/telebot/apihelper.py", line 196, in get_me
    return _make_request(token, method_url)
  File "/home/pi/.local/lib/python3.9/site-packages/telebot/apihelper.py", line 80, in _make_request
    raise Exception('Bot token is not defined')
Exception: Bot token is not defined
"
2023-10-08 23:54:39,385 (__init__.py:960 MainThread) ERROR - TeleBot: "Infinity polling exception: Bot token is not defined"
2023-10-08 23:54:39,386 (__init__.py:962 MainThread) ERROR - TeleBot: "Exception traceback:
Traceback (most recent call last):
  File "/home/pi/.local/lib/python3.9/site-packages/telebot/__init__.py", line 955, in infinity_polling
    self.polling(non_stop=True, timeout=timeout, long_polling_timeout=long_polling_timeout,
  File "/home/pi/.local/lib/python3.9/site-packages/telebot/__init__.py", line 1040, in polling
    logger.info('Starting your bot with username: [@%s]', self.user.username)
  File "/home/pi/.local/lib/python3.9/site-packages/telebot/__init__.py", line 273, in user
    self._user = self.get_me()
  File "/home/pi/.local/lib/python3.9/site-packages/telebot/__init__.py", line 1236, in get_me
    result = apihelper.get_me(self.token)
  File "/home/pi/.local/lib/python3.9/site-packages/telebot/apihelper.py", line 196, in get_me
    return _make_request(token, method_url)
  File "/home/pi/.local/lib/python3.9/site-packages/telebot/apihelper.py", line 80, in _make_request
    raise Exception('Bot token is not defined')
Exception: Bot token is not defined
"
2023-10-08 23:54:42,391 (__init__.py:960 MainThread) ERROR - TeleBot: "Infinity polling exception: Bot token is not defined"
2023-10-08 23:54:42,392 (__init__.py:962 MainThread) ERROR - TeleBot: "Exception traceback:
Traceback (most recent call last):
  File "/home/pi/.local/lib/python3.9/site-packages/telebot/__init__.py", line 955, in infinity_polling
    self.polling(non_stop=True, timeout=timeout, long_polling_timeout=long_polling_timeout,
  File "/home/pi/.local/lib/python3.9/site-packages/telebot/__init__.py", line 1040, in polling
    logger.info('Starting your bot with username: [@%s]', self.user.username)
  File "/home/pi/.local/lib/python3.9/site-packages/telebot/__init__.py", line 273, in user
    self._user = self.get_me()
  File "/home/pi/.local/lib/python3.9/site-packages/telebot/__init__.py", line 1236, in get_me
    result = apihelper.get_me(self.token)
  File "/home/pi/.local/lib/python3.9/site-packages/telebot/apihelper.py", line 196, in get_me
    return _make_request(token, method_url)
  File "/home/pi/.local/lib/python3.9/site-packages/telebot/apihelper.py", line 80, in _make_request
    raise Exception('Bot token is not defined')
Exception: Bot token is not defined
"
2023-10-08 23:54:45,396 (__init__.py:960 MainThread) ERROR - TeleBot: "Infinity polling exception: Bot token is not defined"
2023-10-08 23:54:45,397 (__init__.py:962 MainThread) ERROR - TeleBot: "Exception traceback:
Traceback (most recent call last):
  File "/home/pi/.local/lib/python3.9/site-packages/telebot/__init__.py", line 955, in infinity_polling
    self.polling(non_stop=True, timeout=timeout, long_polling_timeout=long_polling_timeout,
  File "/home/pi/.local/lib/python3.9/site-packages/telebot/__init__.py", line 1040, in polling
    logger.info('Starting your bot with username: [@%s]', self.user.username)
  File "/home/pi/.local/lib/python3.9/site-packages/telebot/__init__.py", line 273, in user
    self._user = self.get_me()
  File "/home/pi/.local/lib/python3.9/site-packages/telebot/__init__.py", line 1236, in get_me
    result = apihelper.get_me(self.token)
  File "/home/pi/.local/lib/python3.9/site-packages/telebot/apihelper.py", line 196, in get_me
    return _make_request(token, method_url)
  File "/home/pi/.local/lib/python3.9/site-packages/telebot/apihelper.py", line 80, in _make_request
    raise Exception('Bot token is not defined')
Exception: Bot token is not defined
"
2023-10-08 23:54:48,401 (__init__.py:960 MainThread) ERROR - TeleBot: "Infinity polling exception: Bot token is not defined"
2023-10-08 23:54:48,402 (__init__.py:962 MainThread) ERROR - TeleBot: "Exception traceback:
Traceback (most recent call last):
  File "/home/pi/.local/lib/python3.9/site-packages/telebot/__init__.py", line 955, in infinity_polling
    self.polling(non_stop=True, timeout=timeout, long_polling_timeout=long_polling_timeout,
  File "/home/pi/.local/lib/python3.9/site-packages/telebot/__init__.py", line 1040, in polling
    logger.info('Starting your bot with username: [@%s]', self.user.username)
  File "/home/pi/.local/lib/python3.9/site-packages/telebot/__init__.py", line 273, in user
    self._user = self.get_me()
  File "/home/pi/.local/lib/python3.9/site-packages/telebot/__init__.py", line 1236, in get_me
    result = apihelper.get_me(self.token)
  File "/home/pi/.local/lib/python3.9/site-packages/telebot/apihelper.py", line 196, in get_me
    return _make_request(token, method_url)
  File "/home/pi/.local/lib/python3.9/site-packages/telebot/apihelper.py", line 80, in _make_request
    raise Exception('Bot token is not defined')
Exception: Bot token is not defined
"
2023-10-08 23:54:51,405 (__init__.py:960 MainThread) ERROR - TeleBot: "Infinity polling exception: Bot token is not defined"
2023-10-08 23:54:51,407 (__init__.py:962 MainThread) ERROR - TeleBot: "Exception traceback:
Traceback (most recent call last):
  File "/home/pi/.local/lib/python3.9/site-packages/telebot/__init__.py", line 955, in infinity_polling
    self.polling(non_stop=True, timeout=timeout, long_polling_timeout=long_polling_timeout,
  File "/home/pi/.local/lib/python3.9/site-packages/telebot/__init__.py", line 1040, in polling
    logger.info('Starting your bot with username: [@%s]', self.user.username)
  File "/home/pi/.local/lib/python3.9/site-packages/telebot/__init__.py", line 273, in user
    self._user = self.get_me()
  File "/home/pi/.local/lib/python3.9/site-packages/telebot/__init__.py", line 1236, in get_me
    result = apihelper.get_me(self.token)
  File "/home/pi/.local/lib/python3.9/site-packages/telebot/apihelper.py", line 196, in get_me
    return _make_request(token, method_url)
  File "/home/pi/.local/lib/python3.9/site-packages/telebot/apihelper.py", line 80, in _make_request
    raise Exception('Bot token is not defined')
Exception: Bot token is not defined
"
2023-10-08 23:54:54,411 (__init__.py:960 MainThread) ERROR - TeleBot: "Infinity polling exception: Bot token is not defined"
2023-10-08 23:54:54,413 (__init__.py:962 MainThread) ERROR - TeleBot: "Exception traceback:
Traceback (most recent call last):
  File "/home/pi/.local/lib/python3.9/site-packages/telebot/__init__.py", line 955, in infinity_polling
    self.polling(non_stop=True, timeout=timeout, long_polling_timeout=long_polling_timeout,
  File "/home/pi/.local/lib/python3.9/site-packages/telebot/__init__.py", line 1040, in polling
    logger.info('Starting your bot with username: [@%s]', self.user.username)
  File "/home/pi/.local/lib/python3.9/site-packages/telebot/__init__.py", line 273, in user
    self._user = self.get_me()
  File "/home/pi/.local/lib/python3.9/site-packages/telebot/__init__.py", line 1236, in get_me
    result = apihelper.get_me(self.token)
  File "/home/pi/.local/lib/python3.9/site-packages/telebot/apihelper.py", line 196, in get_me
    return _make_request(token, method_url)
  File "/home/pi/.local/lib/python3.9/site-packages/telebot/apihelper.py", line 80, in _make_request
    raise Exception('Bot token is not defined')
Exception: Bot token is not defined
"
2023-10-08 23:54:57,416 (__init__.py:960 MainThread) ERROR - TeleBot: "Infinity polling exception: Bot token is not defined"
2023-10-08 23:54:57,417 (__init__.py:962 MainThread) ERROR - TeleBot: "Exception traceback:
Traceback (most recent call last):
  File "/home/pi/.local/lib/python3.9/site-packages/telebot/__init__.py", line 955, in infinity_polling
    self.polling(non_stop=True, timeout=timeout, long_polling_timeout=long_polling_timeout,
  File "/home/pi/.local/lib/python3.9/site-packages/telebot/__init__.py", line 1040, in polling
    logger.info('Starting your bot with username: [@%s]', self.user.username)
  File "/home/pi/.local/lib/python3.9/site-packages/telebot/__init__.py", line 273, in user
    self._user = self.get_me()
  File "/home/pi/.local/lib/python3.9/site-packages/telebot/__init__.py", line 1236, in get_me
    result = apihelper.get_me(self.token)
  File "/home/pi/.local/lib/python3.9/site-packages/telebot/apihelper.py", line 196, in get_me
    return _make_request(token, method_url)
  File "/home/pi/.local/lib/python3.9/site-packages/telebot/apihelper.py", line 80, in _make_request
    raise Exception('Bot token is not defined')
Exception: Bot token is not defined
"
2023-10-08 23:55:00,421 (__init__.py:960 MainThread) ERROR - TeleBot: "Infinity polling exception: Bot token is not defined"
2023-10-08 23:55:00,422 (__init__.py:962 MainThread) ERROR - TeleBot: "Exception traceback:
Traceback (most recent call last):
  File "/home/pi/.local/lib/python3.9/site-packages/telebot/__init__.py", line 955, in infinity_polling
    self.polling(non_stop=True, timeout=timeout, long_polling_timeout=long_polling_timeout,
  File "/home/pi/.local/lib/python3.9/site-packages/telebot/__init__.py", line 1040, in polling
    logger.info('Starting your bot with username: [@%s]', self.user.username)
  File "/home/pi/.local/lib/python3.9/site-packages/telebot/__init__.py", line 273, in user
    self._user = self.get_me()
  File "/home/pi/.local/lib/python3.9/site-packages/telebot/__init__.py", line 1236, in get_me
    result = apihelper.get_me(self.token)
  File "/home/pi/.local/lib/python3.9/site-packages/telebot/apihelper.py", line 196, in get_me
    return _make_request(token, method_url)
  File "/home/pi/.local/lib/python3.9/site-packages/telebot/apihelper.py", line 80, in _make_request
    raise Exception('Bot token is not defined')
Exception: Bot token is not defined
"
2023-10-08 23:55:03,425 (__init__.py:960 MainThread) ERROR - TeleBot: "Infinity polling exception: Bot token is not defined"
2023-10-08 23:55:03,427 (__init__.py:962 MainThread) ERROR - TeleBot: "Exception traceback:
Traceback (most recent call last):
  File "/home/pi/.local/lib/python3.9/site-packages/telebot/__init__.py", line 955, in infinity_polling
    self.polling(non_stop=True, timeout=timeout, long_polling_timeout=long_polling_timeout,
  File "/home/pi/.local/lib/python3.9/site-packages/telebot/__init__.py", line 1040, in polling
    logger.info('Starting your bot with username: [@%s]', self.user.username)
  File "/home/pi/.local/lib/python3.9/site-packages/telebot/__init__.py", line 273, in user
    self._user = self.get_me()
  File "/home/pi/.local/lib/python3.9/site-packages/telebot/__init__.py", line 1236, in get_me
    result = apihelper.get_me(self.token)
  File "/home/pi/.local/lib/python3.9/site-packages/telebot/apihelper.py", line 196, in get_me
    return _make_request(token, method_url)
  File "/home/pi/.local/lib/python3.9/site-packages/telebot/apihelper.py", line 80, in _make_request
    raise Exception('Bot token is not defined')
Exception: Bot token is not defined
"
2023-10-08 23:55:06,432 (__init__.py:960 MainThread) ERROR - TeleBot: "Infinity polling exception: Bot token is not defined"
2023-10-08 23:55:06,433 (__init__.py:962 MainThread) ERROR - TeleBot: "Exception traceback:
Traceback (most recent call last):
  File "/home/pi/.local/lib/python3.9/site-packages/telebot/__init__.py", line 955, in infinity_polling
    self.polling(non_stop=True, timeout=timeout, long_polling_timeout=long_polling_timeout,
  File "/home/pi/.local/lib/python3.9/site-packages/telebot/__init__.py", line 1040, in polling
    logger.info('Starting your bot with username: [@%s]', self.user.username)
  File "/home/pi/.local/lib/python3.9/site-packages/telebot/__init__.py", line 273, in user
    self._user = self.get_me()
  File "/home/pi/.local/lib/python3.9/site-packages/telebot/__init__.py", line 1236, in get_me
    result = apihelper.get_me(self.token)
  File "/home/pi/.local/lib/python3.9/site-packages/telebot/apihelper.py", line 196, in get_me
    return _make_request(token, method_url)
  File "/home/pi/.local/lib/python3.9/site-packages/telebot/apihelper.py", line 80, in _make_request
    raise Exception('Bot token is not defined')
Exception: Bot token is not defined
"
2023-10-08 23:55:09,437 (__init__.py:960 MainThread) ERROR - TeleBot: "Infinity polling exception: Bot token is not defined"
2023-10-08 23:55:09,438 (__init__.py:962 MainThread) ERROR - TeleBot: "Exception traceback:
Traceback (most recent call last):
  File "/home/pi/.local/lib/python3.9/site-packages/telebot/__init__.py", line 955, in infinity_polling
    self.polling(non_stop=True, timeout=timeout, long_polling_timeout=long_polling_timeout,
  File "/home/pi/.local/lib/python3.9/site-packages/telebot/__init__.py", line 1040, in polling
    logger.info('Starting your bot with username: [@%s]', self.user.username)
  File "/home/pi/.local/lib/python3.9/site-packages/telebot/__init__.py", line 273, in user
    self._user = self.get_me()
  File "/home/pi/.local/lib/python3.9/site-packages/telebot/__init__.py", line 1236, in get_me
    result = apihelper.get_me(self.token)
  File "/home/pi/.local/lib/python3.9/site-packages/telebot/apihelper.py", line 196, in get_me
    return _make_request(token, method_url)
  File "/home/pi/.local/lib/python3.9/site-packages/telebot/apihelper.py", line 80, in _make_request
    raise Exception('Bot token is not defined')
Exception: Bot token is not defined
"
2023-10-08 23:55:12,442 (__init__.py:960 MainThread) ERROR - TeleBot: "Infinity polling exception: Bot token is not defined"
2023-10-08 23:55:12,443 (__init__.py:962 MainThread) ERROR - TeleBot: "Exception traceback:
Traceback (most recent call last):
  File "/home/pi/.local/lib/python3.9/site-packages/telebot/__init__.py", line 955, in infinity_polling
    self.polling(non_stop=True, timeout=timeout, long_polling_timeout=long_polling_timeout,
  File "/home/pi/.local/lib/python3.9/site-packages/telebot/__init__.py", line 1040, in polling
    logger.info('Starting your bot with username: [@%s]', self.user.username)
  File "/home/pi/.local/lib/python3.9/site-packages/telebot/__init__.py", line 273, in user
    self._user = self.get_me()
  File "/home/pi/.local/lib/python3.9/site-packages/telebot/__init__.py", line 1236, in get_me
    result = apihelper.get_me(self.token)
  File "/home/pi/.local/lib/python3.9/site-packages/telebot/apihelper.py", line 196, in get_me
    return _make_request(token, method_url)
  File "/home/pi/.local/lib/python3.9/site-packages/telebot/apihelper.py", line 80, in _make_request
    raise Exception('Bot token is not defined')
Exception: Bot token is not defined
"
2023-10-08 23:55:15,446 (__init__.py:960 MainThread) ERROR - TeleBot: "Infinity polling exception: Bot token is not defined"
2023-10-08 23:55:15,448 (__init__.py:962 MainThread) ERROR - TeleBot: "Exception traceback:
Traceback (most recent call last):
  File "/home/pi/.local/lib/python3.9/site-packages/telebot/__init__.py", line 955, in infinity_polling
    self.polling(non_stop=True, timeout=timeout, long_polling_timeout=long_polling_timeout,
  File "/home/pi/.local/lib/python3.9/site-packages/telebot/__init__.py", line 1040, in polling
    logger.info('Starting your bot with username: [@%s]', self.user.username)
  File "/home/pi/.local/lib/python3.9/site-packages/telebot/__init__.py", line 273, in user
    self._user = self.get_me()
  File "/home/pi/.local/lib/python3.9/site-packages/telebot/__init__.py", line 1236, in get_me
    result = apihelper.get_me(self.token)
  File "/home/pi/.local/lib/python3.9/site-packages/telebot/apihelper.py", line 196, in get_me
    return _make_request(token, method_url)
  File "/home/pi/.local/lib/python3.9/site-packages/telebot/apihelper.py", line 80, in _make_request
    raise Exception('Bot token is not defined')
Exception: Bot token is not defined
"
2023-10-08 23:55:18,453 (__init__.py:960 MainThread) ERROR - TeleBot: "Infinity polling exception: Bot token is not defined"
2023-10-08 23:55:18,454 (__init__.py:962 MainThread) ERROR - TeleBot: "Exception traceback:
Traceback (most recent call last):
  File "/home/pi/.local/lib/python3.9/site-packages/telebot/__init__.py", line 955, in infinity_polling
    self.polling(non_stop=True, timeout=timeout, long_polling_timeout=long_polling_timeout,
  File "/home/pi/.local/lib/python3.9/site-packages/telebot/__init__.py", line 1040, in polling
    logger.info('Starting your bot with username: [@%s]', self.user.username)
  File "/home/pi/.local/lib/python3.9/site-packages/telebot/__init__.py", line 273, in user
    self._user = self.get_me()
  File "/home/pi/.local/lib/python3.9/site-packages/telebot/__init__.py", line 1236, in get_me
    result = apihelper.get_me(self.token)
  File "/home/pi/.local/lib/python3.9/site-packages/telebot/apihelper.py", line 196, in get_me
    return _make_request(token, method_url)
  File "/home/pi/.local/lib/python3.9/site-packages/telebot/apihelper.py", line 80, in _make_request
    raise Exception('Bot token is not defined')
Exception: Bot token is not defined
"
2023-10-08 23:55:21,458 (__init__.py:960 MainThread) ERROR - TeleBot: "Infinity polling exception: Bot token is not defined"
2023-10-08 23:55:21,459 (__init__.py:962 MainThread) ERROR - TeleBot: "Exception traceback:
Traceback (most recent call last):
  File "/home/pi/.local/lib/python3.9/site-packages/telebot/__init__.py", line 955, in infinity_polling
    self.polling(non_stop=True, timeout=timeout, long_polling_timeout=long_polling_timeout,
  File "/home/pi/.local/lib/python3.9/site-packages/telebot/__init__.py", line 1040, in polling
    logger.info('Starting your bot with username: [@%s]', self.user.username)
  File "/home/pi/.local/lib/python3.9/site-packages/telebot/__init__.py", line 273, in user
    self._user = self.get_me()
  File "/home/pi/.local/lib/python3.9/site-packages/telebot/__init__.py", line 1236, in get_me
    result = apihelper.get_me(self.token)
  File "/home/pi/.local/lib/python3.9/site-packages/telebot/apihelper.py", line 196, in get_me
    return _make_request(token, method_url)
  File "/home/pi/.local/lib/python3.9/site-packages/telebot/apihelper.py", line 80, in _make_request
    raise Exception('Bot token is not defined')
Exception: Bot token is not defined
"
2023-10-08 23:55:24,465 (__init__.py:960 MainThread) ERROR - TeleBot: "Infinity polling exception: Bot token is not defined"
2023-10-08 23:55:24,466 (__init__.py:962 MainThread) ERROR - TeleBot: "Exception traceback:
Traceback (most recent call last):
  File "/home/pi/.local/lib/python3.9/site-packages/telebot/__init__.py", line 955, in infinity_polling
    self.polling(non_stop=True, timeout=timeout, long_polling_timeout=long_polling_timeout,
  File "/home/pi/.local/lib/python3.9/site-packages/telebot/__init__.py", line 1040, in polling
    logger.info('Starting your bot with username: [@%s]', self.user.username)
  File "/home/pi/.local/lib/python3.9/site-packages/telebot/__init__.py", line 273, in user
    self._user = self.get_me()
  File "/home/pi/.local/lib/python3.9/site-packages/telebot/__init__.py", line 1236, in get_me
    result = apihelper.get_me(self.token)
  File "/home/pi/.local/lib/python3.9/site-packages/telebot/apihelper.py", line 196, in get_me
    return _make_request(token, method_url)
  File "/home/pi/.local/lib/python3.9/site-packages/telebot/apihelper.py", line 80, in _make_request
    raise Exception('Bot token is not defined')
Exception: Bot token is not defined
"
2023-10-08 23:55:27,470 (__init__.py:960 MainThread) ERROR - TeleBot: "Infinity polling exception: Bot token is not defined"
2023-10-08 23:55:27,471 (__init__.py:962 MainThread) ERROR - TeleBot: "Exception traceback:
Traceback (most recent call last):
  File "/home/pi/.local/lib/python3.9/site-packages/telebot/__init__.py", line 955, in infinity_polling
    self.polling(non_stop=True, timeout=timeout, long_polling_timeout=long_polling_timeout,
  File "/home/pi/.local/lib/python3.9/site-packages/telebot/__init__.py", line 1040, in polling
    logger.info('Starting your bot with username: [@%s]', self.user.username)
  File "/home/pi/.local/lib/python3.9/site-packages/telebot/__init__.py", line 273, in user
    self._user = self.get_me()
  File "/home/pi/.local/lib/python3.9/site-packages/telebot/__init__.py", line 1236, in get_me
    result = apihelper.get_me(self.token)
  File "/home/pi/.local/lib/python3.9/site-packages/telebot/apihelper.py", line 196, in get_me
    return _make_request(token, method_url)
  File "/home/pi/.local/lib/python3.9/site-packages/telebot/apihelper.py", line 80, in _make_request
    raise Exception('Bot token is not defined')
Exception: Bot token is not defined
"
2023-10-08 23:55:30,474 (__init__.py:960 MainThread) ERROR - TeleBot: "Infinity polling exception: Bot token is not defined"
2023-10-08 23:55:30,476 (__init__.py:962 MainThread) ERROR - TeleBot: "Exception traceback:
Traceback (most recent call last):
  File "/home/pi/.local/lib/python3.9/site-packages/telebot/__init__.py", line 955, in infinity_polling
    self.polling(non_stop=True, timeout=timeout, long_polling_timeout=long_polling_timeout,
  File "/home/pi/.local/lib/python3.9/site-packages/telebot/__init__.py", line 1040, in polling
    logger.info('Starting your bot with username: [@%s]', self.user.username)
  File "/home/pi/.local/lib/python3.9/site-packages/telebot/__init__.py", line 273, in user
    self._user = self.get_me()
  File "/home/pi/.local/lib/python3.9/site-packages/telebot/__init__.py", line 1236, in get_me
    result = apihelper.get_me(self.token)
  File "/home/pi/.local/lib/python3.9/site-packages/telebot/apihelper.py", line 196, in get_me
    return _make_request(token, method_url)
  File "/home/pi/.local/lib/python3.9/site-packages/telebot/apihelper.py", line 80, in _make_request
    raise Exception('Bot token is not defined')
Exception: Bot token is not defined
"
2023-10-08 23:55:33,479 (__init__.py:960 MainThread) ERROR - TeleBot: "Infinity polling exception: Bot token is not defined"
2023-10-08 23:55:33,481 (__init__.py:962 MainThread) ERROR - TeleBot: "Exception traceback:
Traceback (most recent call last):
  File "/home/pi/.local/lib/python3.9/site-packages/telebot/__init__.py", line 955, in infinity_polling
    self.polling(non_stop=True, timeout=timeout, long_polling_timeout=long_polling_timeout,
  File "/home/pi/.local/lib/python3.9/site-packages/telebot/__init__.py", line 1040, in polling
    logger.info('Starting your bot with username: [@%s]', self.user.username)
  File "/home/pi/.local/lib/python3.9/site-packages/telebot/__init__.py", line 273, in user
    self._user = self.get_me()
  File "/home/pi/.local/lib/python3.9/site-packages/telebot/__init__.py", line 1236, in get_me
    result = apihelper.get_me(self.token)
  File "/home/pi/.local/lib/python3.9/site-packages/telebot/apihelper.py", line 196, in get_me
    return _make_request(token, method_url)
  File "/home/pi/.local/lib/python3.9/site-packages/telebot/apihelper.py", line 80, in _make_request
    raise Exception('Bot token is not defined')
Exception: Bot token is not defined
"
2023-10-08 23:55:36,485 (__init__.py:960 MainThread) ERROR - TeleBot: "Infinity polling exception: Bot token is not defined"
2023-10-08 23:55:36,487 (__init__.py:962 MainThread) ERROR - TeleBot: "Exception traceback:
Traceback (most recent call last):
  File "/home/pi/.local/lib/python3.9/site-packages/telebot/__init__.py", line 955, in infinity_polling
    self.polling(non_stop=True, timeout=timeout, long_polling_timeout=long_polling_timeout,
  File "/home/pi/.local/lib/python3.9/site-packages/telebot/__init__.py", line 1040, in polling
    logger.info('Starting your bot with username: [@%s]', self.user.username)
  File "/home/pi/.local/lib/python3.9/site-packages/telebot/__init__.py", line 273, in user
    self._user = self.get_me()
  File "/home/pi/.local/lib/python3.9/site-packages/telebot/__init__.py", line 1236, in get_me
    result = apihelper.get_me(self.token)
  File "/home/pi/.local/lib/python3.9/site-packages/telebot/apihelper.py", line 196, in get_me
    return _make_request(token, method_url)
  File "/home/pi/.local/lib/python3.9/site-packages/telebot/apihelper.py", line 80, in _make_request
    raise Exception('Bot token is not defined')
Exception: Bot token is not defined
"
2023-10-08 23:55:39,490 (__init__.py:960 MainThread) ERROR - TeleBot: "Infinity polling exception: Bot token is not defined"
2023-10-08 23:55:39,491 (__init__.py:962 MainThread) ERROR - TeleBot: "Exception traceback:
Traceback (most recent call last):
  File "/home/pi/.local/lib/python3.9/site-packages/telebot/__init__.py", line 955, in infinity_polling
    self.polling(non_stop=True, timeout=timeout, long_polling_timeout=long_polling_timeout,
  File "/home/pi/.local/lib/python3.9/site-packages/telebot/__init__.py", line 1040, in polling
    logger.info('Starting your bot with username: [@%s]', self.user.username)
  File "/home/pi/.local/lib/python3.9/site-packages/telebot/__init__.py", line 273, in user
    self._user = self.get_me()
  File "/home/pi/.local/lib/python3.9/site-packages/telebot/__init__.py", line 1236, in get_me
    result = apihelper.get_me(self.token)
  File "/home/pi/.local/lib/python3.9/site-packages/telebot/apihelper.py", line 196, in get_me
    return _make_request(token, method_url)
  File "/home/pi/.local/lib/python3.9/site-packages/telebot/apihelper.py", line 80, in _make_request
    raise Exception('Bot token is not defined')
Exception: Bot token is not defined
"
2023-10-08 23:55:42,495 (__init__.py:960 MainThread) ERROR - TeleBot: "Infinity polling exception: Bot token is not defined"
2023-10-08 23:55:42,496 (__init__.py:962 MainThread) ERROR - TeleBot: "Exception traceback:
Traceback (most recent call last):
  File "/home/pi/.local/lib/python3.9/site-packages/telebot/__init__.py", line 955, in infinity_polling
    self.polling(non_stop=True, timeout=timeout, long_polling_timeout=long_polling_timeout,
  File "/home/pi/.local/lib/python3.9/site-packages/telebot/__init__.py", line 1040, in polling
    logger.info('Starting your bot with username: [@%s]', self.user.username)
  File "/home/pi/.local/lib/python3.9/site-packages/telebot/__init__.py", line 273, in user
    self._user = self.get_me()
  File "/home/pi/.local/lib/python3.9/site-packages/telebot/__init__.py", line 1236, in get_me
    result = apihelper.get_me(self.token)
  File "/home/pi/.local/lib/python3.9/site-packages/telebot/apihelper.py", line 196, in get_me
    return _make_request(token, method_url)
  File "/home/pi/.local/lib/python3.9/site-packages/telebot/apihelper.py", line 80, in _make_request
    raise Exception('Bot token is not defined')
Exception: Bot token is not defined
"
2023-10-08 23:55:45,500 (__init__.py:960 MainThread) ERROR - TeleBot: "Infinity polling exception: Bot token is not defined"
2023-10-08 23:55:45,501 (__init__.py:962 MainThread) ERROR - TeleBot: "Exception traceback:
Traceback (most recent call last):
  File "/home/pi/.local/lib/python3.9/site-packages/telebot/__init__.py", line 955, in infinity_polling
    self.polling(non_stop=True, timeout=timeout, long_polling_timeout=long_polling_timeout,
  File "/home/pi/.local/lib/python3.9/site-packages/telebot/__init__.py", line 1040, in polling
    logger.info('Starting your bot with username: [@%s]', self.user.username)
  File "/home/pi/.local/lib/python3.9/site-packages/telebot/__init__.py", line 273, in user
    self._user = self.get_me()
  File "/home/pi/.local/lib/python3.9/site-packages/telebot/__init__.py", line 1236, in get_me
    result = apihelper.get_me(self.token)
  File "/home/pi/.local/lib/python3.9/site-packages/telebot/apihelper.py", line 196, in get_me
    return _make_request(token, method_url)
  File "/home/pi/.local/lib/python3.9/site-packages/telebot/apihelper.py", line 80, in _make_request
    raise Exception('Bot token is not defined')
Exception: Bot token is not defined
"
2023-10-08 23:55:48,509 (__init__.py:960 MainThread) ERROR - TeleBot: "Infinity polling exception: Bot token is not defined"
2023-10-08 23:55:48,510 (__init__.py:962 MainThread) ERROR - TeleBot: "Exception traceback:
Traceback (most recent call last):
  File "/home/pi/.local/lib/python3.9/site-packages/telebot/__init__.py", line 955, in infinity_polling
    self.polling(non_stop=True, timeout=timeout, long_polling_timeout=long_polling_timeout,
  File "/home/pi/.local/lib/python3.9/site-packages/telebot/__init__.py", line 1040, in polling
    logger.info('Starting your bot with username: [@%s]', self.user.username)
  File "/home/pi/.local/lib/python3.9/site-packages/telebot/__init__.py", line 273, in user
    self._user = self.get_me()
  File "/home/pi/.local/lib/python3.9/site-packages/telebot/__init__.py", line 1236, in get_me
    result = apihelper.get_me(self.token)
  File "/home/pi/.local/lib/python3.9/site-packages/telebot/apihelper.py", line 196, in get_me
    return _make_request(token, method_url)
  File "/home/pi/.local/lib/python3.9/site-packages/telebot/apihelper.py", line 80, in _make_request
    raise Exception('Bot token is not defined')
Exception: Bot token is not defined
"
2023-10-08 23:55:51,514 (__init__.py:960 MainThread) ERROR - TeleBot: "Infinity polling exception: Bot token is not defined"
2023-10-08 23:55:51,515 (__init__.py:962 MainThread) ERROR - TeleBot: "Exception traceback:
Traceback (most recent call last):
  File "/home/pi/.local/lib/python3.9/site-packages/telebot/__init__.py", line 955, in infinity_polling
    self.polling(non_stop=True, timeout=timeout, long_polling_timeout=long_polling_timeout,
  File "/home/pi/.local/lib/python3.9/site-packages/telebot/__init__.py", line 1040, in polling
    logger.info('Starting your bot with username: [@%s]', self.user.username)
  File "/home/pi/.local/lib/python3.9/site-packages/telebot/__init__.py", line 273, in user
    self._user = self.get_me()
  File "/home/pi/.local/lib/python3.9/site-packages/telebot/__init__.py", line 1236, in get_me
    result = apihelper.get_me(self.token)
  File "/home/pi/.local/lib/python3.9/site-packages/telebot/apihelper.py", line 196, in get_me
    return _make_request(token, method_url)
  File "/home/pi/.local/lib/python3.9/site-packages/telebot/apihelper.py", line 80, in _make_request
    raise Exception('Bot token is not defined')
Exception: Bot token is not defined
"
2023-10-08 23:55:54,518 (__init__.py:960 MainThread) ERROR - TeleBot: "Infinity polling exception: Bot token is not defined"
2023-10-08 23:55:54,520 (__init__.py:962 MainThread) ERROR - TeleBot: "Exception traceback:
Traceback (most recent call last):
  File "/home/pi/.local/lib/python3.9/site-packages/telebot/__init__.py", line 955, in infinity_polling
    self.polling(non_stop=True, timeout=timeout, long_polling_timeout=long_polling_timeout,
  File "/home/pi/.local/lib/python3.9/site-packages/telebot/__init__.py", line 1040, in polling
    logger.info('Starting your bot with username: [@%s]', self.user.username)
  File "/home/pi/.local/lib/python3.9/site-packages/telebot/__init__.py", line 273, in user
    self._user = self.get_me()
  File "/home/pi/.local/lib/python3.9/site-packages/telebot/__init__.py", line 1236, in get_me
    result = apihelper.get_me(self.token)
  File "/home/pi/.local/lib/python3.9/site-packages/telebot/apihelper.py", line 196, in get_me
    return _make_request(token, method_url)
  File "/home/pi/.local/lib/python3.9/site-packages/telebot/apihelper.py", line 80, in _make_request
    raise Exception('Bot token is not defined')
Exception: Bot token is not defined
"
2023-10-08 23:55:57,523 (__init__.py:960 MainThread) ERROR - TeleBot: "Infinity polling exception: Bot token is not defined"
2023-10-08 23:55:57,524 (__init__.py:962 MainThread) ERROR - TeleBot: "Exception traceback:
Traceback (most recent call last):
  File "/home/pi/.local/lib/python3.9/site-packages/telebot/__init__.py", line 955, in infinity_polling
    self.polling(non_stop=True, timeout=timeout, long_polling_timeout=long_polling_timeout,
  File "/home/pi/.local/lib/python3.9/site-packages/telebot/__init__.py", line 1040, in polling
    logger.info('Starting your bot with username: [@%s]', self.user.username)
  File "/home/pi/.local/lib/python3.9/site-packages/telebot/__init__.py", line 273, in user
    self._user = self.get_me()
  File "/home/pi/.local/lib/python3.9/site-packages/telebot/__init__.py", line 1236, in get_me
    result = apihelper.get_me(self.token)
  File "/home/pi/.local/lib/python3.9/site-packages/telebot/apihelper.py", line 196, in get_me
    return _make_request(token, method_url)
  File "/home/pi/.local/lib/python3.9/site-packages/telebot/apihelper.py", line 80, in _make_request
    raise Exception('Bot token is not defined')
Exception: Bot token is not defined
"
2023-10-08 23:56:00,529 (__init__.py:960 MainThread) ERROR - TeleBot: "Infinity polling exception: Bot token is not defined"
2023-10-08 23:56:00,531 (__init__.py:962 MainThread) ERROR - TeleBot: "Exception traceback:
Traceback (most recent call last):
  File "/home/pi/.local/lib/python3.9/site-packages/telebot/__init__.py", line 955, in infinity_polling
    self.polling(non_stop=True, timeout=timeout, long_polling_timeout=long_polling_timeout,
  File "/home/pi/.local/lib/python3.9/site-packages/telebot/__init__.py", line 1040, in polling
    logger.info('Starting your bot with username: [@%s]', self.user.username)
  File "/home/pi/.local/lib/python3.9/site-packages/telebot/__init__.py", line 273, in user
    self._user = self.get_me()
  File "/home/pi/.local/lib/python3.9/site-packages/telebot/__init__.py", line 1236, in get_me
    result = apihelper.get_me(self.token)
  File "/home/pi/.local/lib/python3.9/site-packages/telebot/apihelper.py", line 196, in get_me
    return _make_request(token, method_url)
  File "/home/pi/.local/lib/python3.9/site-packages/telebot/apihelper.py", line 80, in _make_request
    raise Exception('Bot token is not defined')
Exception: Bot token is not defined
"
2023-10-08 23:56:03,534 (__init__.py:960 MainThread) ERROR - TeleBot: "Infinity polling exception: Bot token is not defined"
2023-10-08 23:56:03,536 (__init__.py:962 MainThread) ERROR - TeleBot: "Exception traceback:
Traceback (most recent call last):
  File "/home/pi/.local/lib/python3.9/site-packages/telebot/__init__.py", line 955, in infinity_polling
    self.polling(non_stop=True, timeout=timeout, long_polling_timeout=long_polling_timeout,
  File "/home/pi/.local/lib/python3.9/site-packages/telebot/__init__.py", line 1040, in polling
    logger.info('Starting your bot with username: [@%s]', self.user.username)
  File "/home/pi/.local/lib/python3.9/site-packages/telebot/__init__.py", line 273, in user
    self._user = self.get_me()
  File "/home/pi/.local/lib/python3.9/site-packages/telebot/__init__.py", line 1236, in get_me
    result = apihelper.get_me(self.token)
  File "/home/pi/.local/lib/python3.9/site-packages/telebot/apihelper.py", line 196, in get_me
    return _make_request(token, method_url)
  File "/home/pi/.local/lib/python3.9/site-packages/telebot/apihelper.py", line 80, in _make_request
    raise Exception('Bot token is not defined')
Exception: Bot token is not defined
"
2023-10-08 23:56:06,539 (__init__.py:960 MainThread) ERROR - TeleBot: "Infinity polling exception: Bot token is not defined"
2023-10-08 23:56:06,541 (__init__.py:962 MainThread) ERROR - TeleBot: "Exception traceback:
Traceback (most recent call last):
  File "/home/pi/.local/lib/python3.9/site-packages/telebot/__init__.py", line 955, in infinity_polling
    self.polling(non_stop=True, timeout=timeout, long_polling_timeout=long_polling_timeout,
  File "/home/pi/.local/lib/python3.9/site-packages/telebot/__init__.py", line 1040, in polling
    logger.info('Starting your bot with username: [@%s]', self.user.username)
  File "/home/pi/.local/lib/python3.9/site-packages/telebot/__init__.py", line 273, in user
    self._user = self.get_me()
  File "/home/pi/.local/lib/python3.9/site-packages/telebot/__init__.py", line 1236, in get_me
    result = apihelper.get_me(self.token)
  File "/home/pi/.local/lib/python3.9/site-packages/telebot/apihelper.py", line 196, in get_me
    return _make_request(token, method_url)
  File "/home/pi/.local/lib/python3.9/site-packages/telebot/apihelper.py", line 80, in _make_request
    raise Exception('Bot token is not defined')
Exception: Bot token is not defined
"
2023-10-08 23:56:09,544 (__init__.py:960 MainThread) ERROR - TeleBot: "Infinity polling exception: Bot token is not defined"
2023-10-08 23:56:09,545 (__init__.py:962 MainThread) ERROR - TeleBot: "Exception traceback:
Traceback (most recent call last):
  File "/home/pi/.local/lib/python3.9/site-packages/telebot/__init__.py", line 955, in infinity_polling
    self.polling(non_stop=True, timeout=timeout, long_polling_timeout=long_polling_timeout,
  File "/home/pi/.local/lib/python3.9/site-packages/telebot/__init__.py", line 1040, in polling
    logger.info('Starting your bot with username: [@%s]', self.user.username)
  File "/home/pi/.local/lib/python3.9/site-packages/telebot/__init__.py", line 273, in user
    self._user = self.get_me()
  File "/home/pi/.local/lib/python3.9/site-packages/telebot/__init__.py", line 1236, in get_me
    result = apihelper.get_me(self.token)
  File "/home/pi/.local/lib/python3.9/site-packages/telebot/apihelper.py", line 196, in get_me
    return _make_request(token, method_url)
  File "/home/pi/.local/lib/python3.9/site-packages/telebot/apihelper.py", line 80, in _make_request
    raise Exception('Bot token is not defined')
Exception: Bot token is not defined
"
2023-10-08 23:56:12,549 (__init__.py:960 MainThread) ERROR - TeleBot: "Infinity polling exception: Bot token is not defined"
2023-10-08 23:56:12,550 (__init__.py:962 MainThread) ERROR - TeleBot: "Exception traceback:
Traceback (most recent call last):
  File "/home/pi/.local/lib/python3.9/site-packages/telebot/__init__.py", line 955, in infinity_polling
    self.polling(non_stop=True, timeout=timeout, long_polling_timeout=long_polling_timeout,
  File "/home/pi/.local/lib/python3.9/site-packages/telebot/__init__.py", line 1040, in polling
    logger.info('Starting your bot with username: [@%s]', self.user.username)
  File "/home/pi/.local/lib/python3.9/site-packages/telebot/__init__.py", line 273, in user
    self._user = self.get_me()
  File "/home/pi/.local/lib/python3.9/site-packages/telebot/__init__.py", line 1236, in get_me
    result = apihelper.get_me(self.token)
  File "/home/pi/.local/lib/python3.9/site-packages/telebot/apihelper.py", line 196, in get_me
    return _make_request(token, method_url)
  File "/home/pi/.local/lib/python3.9/site-packages/telebot/apihelper.py", line 80, in _make_request
    raise Exception('Bot token is not defined')
Exception: Bot token is not defined
"
2023-10-08 23:56:15,554 (__init__.py:960 MainThread) ERROR - TeleBot: "Infinity polling exception: Bot token is not defined"
2023-10-08 23:56:15,555 (__init__.py:962 MainThread) ERROR - TeleBot: "Exception traceback:
Traceback (most recent call last):
  File "/home/pi/.local/lib/python3.9/site-packages/telebot/__init__.py", line 955, in infinity_polling
    self.polling(non_stop=True, timeout=timeout, long_polling_timeout=long_polling_timeout,
  File "/home/pi/.local/lib/python3.9/site-packages/telebot/__init__.py", line 1040, in polling
    logger.info('Starting your bot with username: [@%s]', self.user.username)
  File "/home/pi/.local/lib/python3.9/site-packages/telebot/__init__.py", line 273, in user
    self._user = self.get_me()
  File "/home/pi/.local/lib/python3.9/site-packages/telebot/__init__.py", line 1236, in get_me
    result = apihelper.get_me(self.token)
  File "/home/pi/.local/lib/python3.9/site-packages/telebot/apihelper.py", line 196, in get_me
    return _make_request(token, method_url)
  File "/home/pi/.local/lib/python3.9/site-packages/telebot/apihelper.py", line 80, in _make_request
    raise Exception('Bot token is not defined')
Exception: Bot token is not defined
"
2023-10-08 23:56:18,559 (__init__.py:960 MainThread) ERROR - TeleBot: "Infinity polling exception: Bot token is not defined"
2023-10-08 23:56:18,560 (__init__.py:962 MainThread) ERROR - TeleBot: "Exception traceback:
Traceback (most recent call last):
  File "/home/pi/.local/lib/python3.9/site-packages/telebot/__init__.py", line 955, in infinity_polling
    self.polling(non_stop=True, timeout=timeout, long_polling_timeout=long_polling_timeout,
  File "/home/pi/.local/lib/python3.9/site-packages/telebot/__init__.py", line 1040, in polling
    logger.info('Starting your bot with username: [@%s]', self.user.username)
  File "/home/pi/.local/lib/python3.9/site-packages/telebot/__init__.py", line 273, in user
    self._user = self.get_me()
  File "/home/pi/.local/lib/python3.9/site-packages/telebot/__init__.py", line 1236, in get_me
    result = apihelper.get_me(self.token)
  File "/home/pi/.local/lib/python3.9/site-packages/telebot/apihelper.py", line 196, in get_me
    return _make_request(token, method_url)
  File "/home/pi/.local/lib/python3.9/site-packages/telebot/apihelper.py", line 80, in _make_request
    raise Exception('Bot token is not defined')
Exception: Bot token is not defined
"
2023-10-08 23:56:21,563 (__init__.py:960 MainThread) ERROR - TeleBot: "Infinity polling exception: Bot token is not defined"
2023-10-08 23:56:21,565 (__init__.py:962 MainThread) ERROR - TeleBot: "Exception traceback:
Traceback (most recent call last):
  File "/home/pi/.local/lib/python3.9/site-packages/telebot/__init__.py", line 955, in infinity_polling
    self.polling(non_stop=True, timeout=timeout, long_polling_timeout=long_polling_timeout,
  File "/home/pi/.local/lib/python3.9/site-packages/telebot/__init__.py", line 1040, in polling
    logger.info('Starting your bot with username: [@%s]', self.user.username)
  File "/home/pi/.local/lib/python3.9/site-packages/telebot/__init__.py", line 273, in user
    self._user = self.get_me()
  File "/home/pi/.local/lib/python3.9/site-packages/telebot/__init__.py", line 1236, in get_me
    result = apihelper.get_me(self.token)
  File "/home/pi/.local/lib/python3.9/site-packages/telebot/apihelper.py", line 196, in get_me
    return _make_request(token, method_url)
  File "/home/pi/.local/lib/python3.9/site-packages/telebot/apihelper.py", line 80, in _make_request
    raise Exception('Bot token is not defined')
Exception: Bot token is not defined
"
2023-10-08 23:56:24,568 (__init__.py:960 MainThread) ERROR - TeleBot: "Infinity polling exception: Bot token is not defined"
2023-10-08 23:56:24,569 (__init__.py:962 MainThread) ERROR - TeleBot: "Exception traceback:
Traceback (most recent call last):
  File "/home/pi/.local/lib/python3.9/site-packages/telebot/__init__.py", line 955, in infinity_polling
    self.polling(non_stop=True, timeout=timeout, long_polling_timeout=long_polling_timeout,
  File "/home/pi/.local/lib/python3.9/site-packages/telebot/__init__.py", line 1040, in polling
    logger.info('Starting your bot with username: [@%s]', self.user.username)
  File "/home/pi/.local/lib/python3.9/site-packages/telebot/__init__.py", line 273, in user
    self._user = self.get_me()
  File "/home/pi/.local/lib/python3.9/site-packages/telebot/__init__.py", line 1236, in get_me
    result = apihelper.get_me(self.token)
  File "/home/pi/.local/lib/python3.9/site-packages/telebot/apihelper.py", line 196, in get_me
    return _make_request(token, method_url)
  File "/home/pi/.local/lib/python3.9/site-packages/telebot/apihelper.py", line 80, in _make_request
    raise Exception('Bot token is not defined')
Exception: Bot token is not defined
"
2023-10-08 23:56:27,573 (__init__.py:960 MainThread) ERROR - TeleBot: "Infinity polling exception: Bot token is not defined"
2023-10-08 23:56:27,574 (__init__.py:962 MainThread) ERROR - TeleBot: "Exception traceback:
Traceback (most recent call last):
  File "/home/pi/.local/lib/python3.9/site-packages/telebot/__init__.py", line 955, in infinity_polling
    self.polling(non_stop=True, timeout=timeout, long_polling_timeout=long_polling_timeout,
  File "/home/pi/.local/lib/python3.9/site-packages/telebot/__init__.py", line 1040, in polling
    logger.info('Starting your bot with username: [@%s]', self.user.username)
  File "/home/pi/.local/lib/python3.9/site-packages/telebot/__init__.py", line 273, in user
    self._user = self.get_me()
  File "/home/pi/.local/lib/python3.9/site-packages/telebot/__init__.py", line 1236, in get_me
    result = apihelper.get_me(self.token)
  File "/home/pi/.local/lib/python3.9/site-packages/telebot/apihelper.py", line 196, in get_me
    return _make_request(token, method_url)
  File "/home/pi/.local/lib/python3.9/site-packages/telebot/apihelper.py", line 80, in _make_request
    raise Exception('Bot token is not defined')
Exception: Bot token is not defined
"
2023-10-08 23:56:30,578 (__init__.py:960 MainThread) ERROR - TeleBot: "Infinity polling exception: Bot token is not defined"
2023-10-08 23:56:30,579 (__init__.py:962 MainThread) ERROR - TeleBot: "Exception traceback:
Traceback (most recent call last):
  File "/home/pi/.local/lib/python3.9/site-packages/telebot/__init__.py", line 955, in infinity_polling
    self.polling(non_stop=True, timeout=timeout, long_polling_timeout=long_polling_timeout,
  File "/home/pi/.local/lib/python3.9/site-packages/telebot/__init__.py", line 1040, in polling
    logger.info('Starting your bot with username: [@%s]', self.user.username)
  File "/home/pi/.local/lib/python3.9/site-packages/telebot/__init__.py", line 273, in user
    self._user = self.get_me()
  File "/home/pi/.local/lib/python3.9/site-packages/telebot/__init__.py", line 1236, in get_me
    result = apihelper.get_me(self.token)
  File "/home/pi/.local/lib/python3.9/site-packages/telebot/apihelper.py", line 196, in get_me
    return _make_request(token, method_url)
  File "/home/pi/.local/lib/python3.9/site-packages/telebot/apihelper.py", line 80, in _make_request
    raise Exception('Bot token is not defined')
Exception: Bot token is not defined
"
2023-10-08 23:56:33,582 (__init__.py:960 MainThread) ERROR - TeleBot: "Infinity polling exception: Bot token is not defined"
2023-10-08 23:56:33,584 (__init__.py:962 MainThread) ERROR - TeleBot: "Exception traceback:
Traceback (most recent call last):
  File "/home/pi/.local/lib/python3.9/site-packages/telebot/__init__.py", line 955, in infinity_polling
    self.polling(non_stop=True, timeout=timeout, long_polling_timeout=long_polling_timeout,
  File "/home/pi/.local/lib/python3.9/site-packages/telebot/__init__.py", line 1040, in polling
    logger.info('Starting your bot with username: [@%s]', self.user.username)
  File "/home/pi/.local/lib/python3.9/site-packages/telebot/__init__.py", line 273, in user
    self._user = self.get_me()
  File "/home/pi/.local/lib/python3.9/site-packages/telebot/__init__.py", line 1236, in get_me
    result = apihelper.get_me(self.token)
  File "/home/pi/.local/lib/python3.9/site-packages/telebot/apihelper.py", line 196, in get_me
    return _make_request(token, method_url)
  File "/home/pi/.local/lib/python3.9/site-packages/telebot/apihelper.py", line 80, in _make_request
    raise Exception('Bot token is not defined')
Exception: Bot token is not defined
"
2023-10-08 23:56:36,587 (__init__.py:960 MainThread) ERROR - TeleBot: "Infinity polling exception: Bot token is not defined"
2023-10-08 23:56:36,589 (__init__.py:962 MainThread) ERROR - TeleBot: "Exception traceback:
Traceback (most recent call last):
  File "/home/pi/.local/lib/python3.9/site-packages/telebot/__init__.py", line 955, in infinity_polling
    self.polling(non_stop=True, timeout=timeout, long_polling_timeout=long_polling_timeout,
  File "/home/pi/.local/lib/python3.9/site-packages/telebot/__init__.py", line 1040, in polling
    logger.info('Starting your bot with username: [@%s]', self.user.username)
  File "/home/pi/.local/lib/python3.9/site-packages/telebot/__init__.py", line 273, in user
    self._user = self.get_me()
  File "/home/pi/.local/lib/python3.9/site-packages/telebot/__init__.py", line 1236, in get_me
    result = apihelper.get_me(self.token)
  File "/home/pi/.local/lib/python3.9/site-packages/telebot/apihelper.py", line 196, in get_me
    return _make_request(token, method_url)
  File "/home/pi/.local/lib/python3.9/site-packages/telebot/apihelper.py", line 80, in _make_request
    raise Exception('Bot token is not defined')
Exception: Bot token is not defined
"
2023-10-08 23:56:39,592 (__init__.py:960 MainThread) ERROR - TeleBot: "Infinity polling exception: Bot token is not defined"
2023-10-08 23:56:39,593 (__init__.py:962 MainThread) ERROR - TeleBot: "Exception traceback:
Traceback (most recent call last):
  File "/home/pi/.local/lib/python3.9/site-packages/telebot/__init__.py", line 955, in infinity_polling
    self.polling(non_stop=True, timeout=timeout, long_polling_timeout=long_polling_timeout,
  File "/home/pi/.local/lib/python3.9/site-packages/telebot/__init__.py", line 1040, in polling
    logger.info('Starting your bot with username: [@%s]', self.user.username)
  File "/home/pi/.local/lib/python3.9/site-packages/telebot/__init__.py", line 273, in user
    self._user = self.get_me()
  File "/home/pi/.local/lib/python3.9/site-packages/telebot/__init__.py", line 1236, in get_me
    result = apihelper.get_me(self.token)
  File "/home/pi/.local/lib/python3.9/site-packages/telebot/apihelper.py", line 196, in get_me
    return _make_request(token, method_url)
  File "/home/pi/.local/lib/python3.9/site-packages/telebot/apihelper.py", line 80, in _make_request
    raise Exception('Bot token is not defined')
Exception: Bot token is not defined
"
2023-10-08 23:56:42,597 (__init__.py:960 MainThread) ERROR - TeleBot: "Infinity polling exception: Bot token is not defined"
2023-10-08 23:56:42,598 (__init__.py:962 MainThread) ERROR - TeleBot: "Exception traceback:
Traceback (most recent call last):
  File "/home/pi/.local/lib/python3.9/site-packages/telebot/__init__.py", line 955, in infinity_polling
    self.polling(non_stop=True, timeout=timeout, long_polling_timeout=long_polling_timeout,
  File "/home/pi/.local/lib/python3.9/site-packages/telebot/__init__.py", line 1040, in polling
    logger.info('Starting your bot with username: [@%s]', self.user.username)
  File "/home/pi/.local/lib/python3.9/site-packages/telebot/__init__.py", line 273, in user
    self._user = self.get_me()
  File "/home/pi/.local/lib/python3.9/site-packages/telebot/__init__.py", line 1236, in get_me
    result = apihelper.get_me(self.token)
  File "/home/pi/.local/lib/python3.9/site-packages/telebot/apihelper.py", line 196, in get_me
    return _make_request(token, method_url)
  File "/home/pi/.local/lib/python3.9/site-packages/telebot/apihelper.py", line 80, in _make_request
    raise Exception('Bot token is not defined')
Exception: Bot token is not defined
"
2023-10-08 23:56:45,602 (__init__.py:960 MainThread) ERROR - TeleBot: "Infinity polling exception: Bot token is not defined"
2023-10-08 23:56:45,603 (__init__.py:962 MainThread) ERROR - TeleBot: "Exception traceback:
Traceback (most recent call last):
  File "/home/pi/.local/lib/python3.9/site-packages/telebot/__init__.py", line 955, in infinity_polling
    self.polling(non_stop=True, timeout=timeout, long_polling_timeout=long_polling_timeout,
  File "/home/pi/.local/lib/python3.9/site-packages/telebot/__init__.py", line 1040, in polling
    logger.info('Starting your bot with username: [@%s]', self.user.username)
  File "/home/pi/.local/lib/python3.9/site-packages/telebot/__init__.py", line 273, in user
    self._user = self.get_me()
  File "/home/pi/.local/lib/python3.9/site-packages/telebot/__init__.py", line 1236, in get_me
    result = apihelper.get_me(self.token)
  File "/home/pi/.local/lib/python3.9/site-packages/telebot/apihelper.py", line 196, in get_me
    return _make_request(token, method_url)
  File "/home/pi/.local/lib/python3.9/site-packages/telebot/apihelper.py", line 80, in _make_request
    raise Exception('Bot token is not defined')
Exception: Bot token is not defined
"
2023-10-08 23:56:48,604 (__init__.py:960 MainThread) ERROR - TeleBot: "Infinity polling exception: Bot token is not defined"
2023-10-08 23:56:48,605 (__init__.py:962 MainThread) ERROR - TeleBot: "Exception traceback:
Traceback (most recent call last):
  File "/home/pi/.local/lib/python3.9/site-packages/telebot/__init__.py", line 955, in infinity_polling
    self.polling(non_stop=True, timeout=timeout, long_polling_timeout=long_polling_timeout,
  File "/home/pi/.local/lib/python3.9/site-packages/telebot/__init__.py", line 1040, in polling
    logger.info('Starting your bot with username: [@%s]', self.user.username)
  File "/home/pi/.local/lib/python3.9/site-packages/telebot/__init__.py", line 273, in user
    self._user = self.get_me()
  File "/home/pi/.local/lib/python3.9/site-packages/telebot/__init__.py", line 1236, in get_me
    result = apihelper.get_me(self.token)
  File "/home/pi/.local/lib/python3.9/site-packages/telebot/apihelper.py", line 196, in get_me
    return _make_request(token, method_url)
  File "/home/pi/.local/lib/python3.9/site-packages/telebot/apihelper.py", line 80, in _make_request
    raise Exception('Bot token is not defined')
Exception: Bot token is not defined
"
2023-10-08 23:56:51,606 (__init__.py:960 MainThread) ERROR - TeleBot: "Infinity polling exception: Bot token is not defined"
2023-10-08 23:56:51,606 (__init__.py:962 MainThread) ERROR - TeleBot: "Exception traceback:
Traceback (most recent call last):
  File "/home/pi/.local/lib/python3.9/site-packages/telebot/__init__.py", line 955, in infinity_polling
    self.polling(non_stop=True, timeout=timeout, long_polling_timeout=long_polling_timeout,
  File "/home/pi/.local/lib/python3.9/site-packages/telebot/__init__.py", line 1040, in polling
    logger.info('Starting your bot with username: [@%s]', self.user.username)
  File "/home/pi/.local/lib/python3.9/site-packages/telebot/__init__.py", line 273, in user
    self._user = self.get_me()
  File "/home/pi/.local/lib/python3.9/site-packages/telebot/__init__.py", line 1236, in get_me
    result = apihelper.get_me(self.token)
  File "/home/pi/.local/lib/python3.9/site-packages/telebot/apihelper.py", line 196, in get_me
    return _make_request(token, method_url)
  File "/home/pi/.local/lib/python3.9/site-packages/telebot/apihelper.py", line 80, in _make_request
    raise Exception('Bot token is not defined')
Exception: Bot token is not defined
"
2023-10-08 23:56:54,610 (__init__.py:960 MainThread) ERROR - TeleBot: "Infinity polling exception: Bot token is not defined"
2023-10-08 23:56:54,611 (__init__.py:962 MainThread) ERROR - TeleBot: "Exception traceback:
Traceback (most recent call last):
  File "/home/pi/.local/lib/python3.9/site-packages/telebot/__init__.py", line 955, in infinity_polling
    self.polling(non_stop=True, timeout=timeout, long_polling_timeout=long_polling_timeout,
  File "/home/pi/.local/lib/python3.9/site-packages/telebot/__init__.py", line 1040, in polling
    logger.info('Starting your bot with username: [@%s]', self.user.username)
  File "/home/pi/.local/lib/python3.9/site-packages/telebot/__init__.py", line 273, in user
    self._user = self.get_me()
  File "/home/pi/.local/lib/python3.9/site-packages/telebot/__init__.py", line 1236, in get_me
    result = apihelper.get_me(self.token)
  File "/home/pi/.local/lib/python3.9/site-packages/telebot/apihelper.py", line 196, in get_me
    return _make_request(token, method_url)
  File "/home/pi/.local/lib/python3.9/site-packages/telebot/apihelper.py", line 80, in _make_request
    raise Exception('Bot token is not defined')
Exception: Bot token is not defined
"
2023-10-08 23:56:57,614 (__init__.py:960 MainThread) ERROR - TeleBot: "Infinity polling exception: Bot token is not defined"
2023-10-08 23:56:57,615 (__init__.py:962 MainThread) ERROR - TeleBot: "Exception traceback:
Traceback (most recent call last):
  File "/home/pi/.local/lib/python3.9/site-packages/telebot/__init__.py", line 955, in infinity_polling
    self.polling(non_stop=True, timeout=timeout, long_polling_timeout=long_polling_timeout,
  File "/home/pi/.local/lib/python3.9/site-packages/telebot/__init__.py", line 1040, in polling
    logger.info('Starting your bot with username: [@%s]', self.user.username)
  File "/home/pi/.local/lib/python3.9/site-packages/telebot/__init__.py", line 273, in user
    self._user = self.get_me()
  File "/home/pi/.local/lib/python3.9/site-packages/telebot/__init__.py", line 1236, in get_me
    result = apihelper.get_me(self.token)
  File "/home/pi/.local/lib/python3.9/site-packages/telebot/apihelper.py", line 196, in get_me
    return _make_request(token, method_url)
  File "/home/pi/.local/lib/python3.9/site-packages/telebot/apihelper.py", line 80, in _make_request
    raise Exception('Bot token is not defined')
Exception: Bot token is not defined
"
2023-10-08 23:57:00,619 (__init__.py:960 MainThread) ERROR - TeleBot: "Infinity polling exception: Bot token is not defined"
2023-10-08 23:57:00,621 (__init__.py:962 MainThread) ERROR - TeleBot: "Exception traceback:
Traceback (most recent call last):
  File "/home/pi/.local/lib/python3.9/site-packages/telebot/__init__.py", line 955, in infinity_polling
    self.polling(non_stop=True, timeout=timeout, long_polling_timeout=long_polling_timeout,
  File "/home/pi/.local/lib/python3.9/site-packages/telebot/__init__.py", line 1040, in polling
    logger.info('Starting your bot with username: [@%s]', self.user.username)
  File "/home/pi/.local/lib/python3.9/site-packages/telebot/__init__.py", line 273, in user
    self._user = self.get_me()
  File "/home/pi/.local/lib/python3.9/site-packages/telebot/__init__.py", line 1236, in get_me
    result = apihelper.get_me(self.token)
  File "/home/pi/.local/lib/python3.9/site-packages/telebot/apihelper.py", line 196, in get_me
    return _make_request(token, method_url)
  File "/home/pi/.local/lib/python3.9/site-packages/telebot/apihelper.py", line 80, in _make_request
    raise Exception('Bot token is not defined')
Exception: Bot token is not defined
"
2023-10-08 23:57:03,624 (__init__.py:960 MainThread) ERROR - TeleBot: "Infinity polling exception: Bot token is not defined"
2023-10-08 23:57:03,625 (__init__.py:962 MainThread) ERROR - TeleBot: "Exception traceback:
Traceback (most recent call last):
  File "/home/pi/.local/lib/python3.9/site-packages/telebot/__init__.py", line 955, in infinity_polling
    self.polling(non_stop=True, timeout=timeout, long_polling_timeout=long_polling_timeout,
  File "/home/pi/.local/lib/python3.9/site-packages/telebot/__init__.py", line 1040, in polling
    logger.info('Starting your bot with username: [@%s]', self.user.username)
  File "/home/pi/.local/lib/python3.9/site-packages/telebot/__init__.py", line 273, in user
    self._user = self.get_me()
  File "/home/pi/.local/lib/python3.9/site-packages/telebot/__init__.py", line 1236, in get_me
    result = apihelper.get_me(self.token)
  File "/home/pi/.local/lib/python3.9/site-packages/telebot/apihelper.py", line 196, in get_me
    return _make_request(token, method_url)
  File "/home/pi/.local/lib/python3.9/site-packages/telebot/apihelper.py", line 80, in _make_request
    raise Exception('Bot token is not defined')
Exception: Bot token is not defined
"
2023-10-08 23:57:06,627 (__init__.py:960 MainThread) ERROR - TeleBot: "Infinity polling exception: Bot token is not defined"
2023-10-08 23:57:06,628 (__init__.py:962 MainThread) ERROR - TeleBot: "Exception traceback:
Traceback (most recent call last):
  File "/home/pi/.local/lib/python3.9/site-packages/telebot/__init__.py", line 955, in infinity_polling
    self.polling(non_stop=True, timeout=timeout, long_polling_timeout=long_polling_timeout,
  File "/home/pi/.local/lib/python3.9/site-packages/telebot/__init__.py", line 1040, in polling
    logger.info('Starting your bot with username: [@%s]', self.user.username)
  File "/home/pi/.local/lib/python3.9/site-packages/telebot/__init__.py", line 273, in user
    self._user = self.get_me()
  File "/home/pi/.local/lib/python3.9/site-packages/telebot/__init__.py", line 1236, in get_me
    result = apihelper.get_me(self.token)
  File "/home/pi/.local/lib/python3.9/site-packages/telebot/apihelper.py", line 196, in get_me
    return _make_request(token, method_url)
  File "/home/pi/.local/lib/python3.9/site-packages/telebot/apihelper.py", line 80, in _make_request
    raise Exception('Bot token is not defined')
Exception: Bot token is not defined
"
2023-10-08 23:57:09,632 (__init__.py:960 MainThread) ERROR - TeleBot: "Infinity polling exception: Bot token is not defined"
2023-10-08 23:57:09,633 (__init__.py:962 MainThread) ERROR - TeleBot: "Exception traceback:
Traceback (most recent call last):
  File "/home/pi/.local/lib/python3.9/site-packages/telebot/__init__.py", line 955, in infinity_polling
    self.polling(non_stop=True, timeout=timeout, long_polling_timeout=long_polling_timeout,
  File "/home/pi/.local/lib/python3.9/site-packages/telebot/__init__.py", line 1040, in polling
    logger.info('Starting your bot with username: [@%s]', self.user.username)
  File "/home/pi/.local/lib/python3.9/site-packages/telebot/__init__.py", line 273, in user
    self._user = self.get_me()
  File "/home/pi/.local/lib/python3.9/site-packages/telebot/__init__.py", line 1236, in get_me
    result = apihelper.get_me(self.token)
  File "/home/pi/.local/lib/python3.9/site-packages/telebot/apihelper.py", line 196, in get_me
    return _make_request(token, method_url)
  File "/home/pi/.local/lib/python3.9/site-packages/telebot/apihelper.py", line 80, in _make_request
    raise Exception('Bot token is not defined')
Exception: Bot token is not defined
"
2023-10-08 23:57:12,637 (__init__.py:960 MainThread) ERROR - TeleBot: "Infinity polling exception: Bot token is not defined"
2023-10-08 23:57:12,638 (__init__.py:962 MainThread) ERROR - TeleBot: "Exception traceback:
Traceback (most recent call last):
  File "/home/pi/.local/lib/python3.9/site-packages/telebot/__init__.py", line 955, in infinity_polling
    self.polling(non_stop=True, timeout=timeout, long_polling_timeout=long_polling_timeout,
  File "/home/pi/.local/lib/python3.9/site-packages/telebot/__init__.py", line 1040, in polling
    logger.info('Starting your bot with username: [@%s]', self.user.username)
  File "/home/pi/.local/lib/python3.9/site-packages/telebot/__init__.py", line 273, in user
    self._user = self.get_me()
  File "/home/pi/.local/lib/python3.9/site-packages/telebot/__init__.py", line 1236, in get_me
    result = apihelper.get_me(self.token)
  File "/home/pi/.local/lib/python3.9/site-packages/telebot/apihelper.py", line 196, in get_me
    return _make_request(token, method_url)
  File "/home/pi/.local/lib/python3.9/site-packages/telebot/apihelper.py", line 80, in _make_request
    raise Exception('Bot token is not defined')
Exception: Bot token is not defined
"
2023-10-08 23:57:15,641 (__init__.py:960 MainThread) ERROR - TeleBot: "Infinity polling exception: Bot token is not defined"
2023-10-08 23:57:15,642 (__init__.py:962 MainThread) ERROR - TeleBot: "Exception traceback:
Traceback (most recent call last):
  File "/home/pi/.local/lib/python3.9/site-packages/telebot/__init__.py", line 955, in infinity_polling
    self.polling(non_stop=True, timeout=timeout, long_polling_timeout=long_polling_timeout,
  File "/home/pi/.local/lib/python3.9/site-packages/telebot/__init__.py", line 1040, in polling
    logger.info('Starting your bot with username: [@%s]', self.user.username)
  File "/home/pi/.local/lib/python3.9/site-packages/telebot/__init__.py", line 273, in user
    self._user = self.get_me()
  File "/home/pi/.local/lib/python3.9/site-packages/telebot/__init__.py", line 1236, in get_me
    result = apihelper.get_me(self.token)
  File "/home/pi/.local/lib/python3.9/site-packages/telebot/apihelper.py", line 196, in get_me
    return _make_request(token, method_url)
  File "/home/pi/.local/lib/python3.9/site-packages/telebot/apihelper.py", line 80, in _make_request
    raise Exception('Bot token is not defined')
Exception: Bot token is not defined
"
2023-10-08 23:57:18,645 (__init__.py:960 MainThread) ERROR - TeleBot: "Infinity polling exception: Bot token is not defined"
2023-10-08 23:57:18,646 (__init__.py:962 MainThread) ERROR - TeleBot: "Exception traceback:
Traceback (most recent call last):
  File "/home/pi/.local/lib/python3.9/site-packages/telebot/__init__.py", line 955, in infinity_polling
    self.polling(non_stop=True, timeout=timeout, long_polling_timeout=long_polling_timeout,
  File "/home/pi/.local/lib/python3.9/site-packages/telebot/__init__.py", line 1040, in polling
    logger.info('Starting your bot with username: [@%s]', self.user.username)
  File "/home/pi/.local/lib/python3.9/site-packages/telebot/__init__.py", line 273, in user
    self._user = self.get_me()
  File "/home/pi/.local/lib/python3.9/site-packages/telebot/__init__.py", line 1236, in get_me
    result = apihelper.get_me(self.token)
  File "/home/pi/.local/lib/python3.9/site-packages/telebot/apihelper.py", line 196, in get_me
    return _make_request(token, method_url)
  File "/home/pi/.local/lib/python3.9/site-packages/telebot/apihelper.py", line 80, in _make_request
    raise Exception('Bot token is not defined')
Exception: Bot token is not defined
"
